Traceback (most recent call last):
  File "/home/keeeto/mambaforge/envs/ebook/lib/python3.6/site-packages/jupyter_cache/executors/utils.py", line 56, in single_nb_execution
    record_timing=False,
  File "/home/keeeto/mambaforge/envs/ebook/lib/python3.6/site-packages/nbclient/client.py", line 1093, in execute
    return NotebookClient(nb=nb, resources=resources, km=km, **kwargs).execute()
  File "/home/keeeto/mambaforge/envs/ebook/lib/python3.6/site-packages/nbclient/util.py", line 84, in wrapped
    return just_run(coro(*args, **kwargs))
  File "/home/keeeto/mambaforge/envs/ebook/lib/python3.6/site-packages/nbclient/util.py", line 62, in just_run
    return loop.run_until_complete(coro)
  File "/home/keeeto/mambaforge/envs/ebook/lib/python3.6/asyncio/base_events.py", line 488, in run_until_complete
    return future.result()
  File "/home/keeeto/mambaforge/envs/ebook/lib/python3.6/site-packages/nbclient/client.py", line 560, in async_execute
    cell, index, execution_count=self.code_cells_executed + 1
  File "/home/keeeto/mambaforge/envs/ebook/lib/python3.6/site-packages/nbclient/client.py", line 854, in async_execute_cell
    self._check_raise_for_error(cell, exec_reply)
  File "/home/keeeto/mambaforge/envs/ebook/lib/python3.6/site-packages/nbclient/client.py", line 756, in _check_raise_for_error
    raise CellExecutionError.from_cell_and_msg(cell, exec_reply_content)
nbclient.exceptions.CellExecutionError: An error occurred while executing the following cell:
------------------
# sklearn
from sklearn.datasets import make_blobs
from sklearn.cluster import KMeans
from sklearn.mixture import GaussianMixture as GMM
from sklearn.mixture import BayesianGaussianMixture as BGM
from sklearn.datasets import make_moons
from sklearn import metrics
import sklearn.datasets

# helpers
import numpy as np
import matplotlib.pyplot as plt
from matplotlib import cm
import matplotlib as mpl
plt.style.use('ggplot')
------------------

[0;31m---------------------------------------------------------------------------[0m
[0;31mModuleNotFoundError[0m                       Traceback (most recent call last)
[0;32m<ipython-input-1-d7df248635dc>[0m in [0;36m<module>[0;34m[0m
[1;32m      1[0m [0;31m# sklearn[0m[0;34m[0m[0;34m[0m[0;34m[0m[0m
[0;32m----> 2[0;31m [0;32mfrom[0m [0msklearn[0m[0;34m.[0m[0mdatasets[0m [0;32mimport[0m [0mmake_blobs[0m[0;34m[0m[0;34m[0m[0m
[0m[1;32m      3[0m [0;32mfrom[0m [0msklearn[0m[0;34m.[0m[0mcluster[0m [0;32mimport[0m [0mKMeans[0m[0;34m[0m[0;34m[0m[0m
[1;32m      4[0m [0;32mfrom[0m [0msklearn[0m[0;34m.[0m[0mmixture[0m [0;32mimport[0m [0mGaussianMixture[0m [0;32mas[0m [0mGMM[0m[0;34m[0m[0;34m[0m[0m
[1;32m      5[0m [0;32mfrom[0m [0msklearn[0m[0;34m.[0m[0mmixture[0m [0;32mimport[0m [0mBayesianGaussianMixture[0m [0;32mas[0m [0mBGM[0m[0;34m[0m[0;34m[0m[0m

[0;31mModuleNotFoundError[0m: No module named 'sklearn'
ModuleNotFoundError: No module named 'sklearn'

